<?xml version="1.0" encoding="utf-8"?>
<!-- This URDF was automatically created by SolidWorks to URDF Exporter! Originally created by Stephen Brawner (brawner@gmail.com) 
     Commit Version: 1.6.0-4-g7f85cfe  Build Version: 1.6.7995.38578
     For more information, please see http://wiki.ros.org/sw_urdf_exporter -->
<robot
  name="autonomous_robot_description">

  <link name="base_footprint">
      <origin xyz="0 0 0" rpy="0 0 0" />
  </link>

  <joint name="base_footprint_to_base_link" type="fixed">
    <parent link="base_footprint"/>
    <child link="base_link"/>
    <origin xyz="0 0 0.45" rpy="0 0 0"/>
  </joint>
  
  <link
    name="base_link">
    <inertial>
      <origin
        xyz="0.00455949538882372 2.98072989951548E-05 -0.00732133437147531"
        rpy="0 0 0" />
      <mass
        value="3.98044471341497" />
      <inertia
        ixx="0.0309523235772865"
        ixy="-3.26148793314342E-09"
        ixz="-6.92311630980574E-05"
        iyy="0.0917035140024459"
        iyz="3.21324609254823E-08"
        izz="0.116670838462844" />
    </inertial>

    <visual>
      <origin
        xyz="0 0 0"
        rpy="0 0 0" />
      <geometry>
          <mesh filename="package://autonomous_robot_description/meshes/base_link.stl"/>
      </geometry>
      <material
        name="">
        <color
          rgba="0.752941176470588 0.752941176470588 0.752941176470588 1" />
      </material>
    </visual>

    <collision>
      <origin
        xyz="0 0 0"
        rpy="0 0 0" />
      <geometry>
        <mesh filename="package://autonomous_robot_description/meshes/base_link.stl"/>
      </geometry>
    </collision>
  </link>

  <link
    name="front_hinge">
    <inertial>
      <origin
        xyz="-6.66133814775094E-15 0 0.104803731952649"
        rpy="0 0 0" />
      <mass
        value="0.146953839835609" />
      <inertia
        ixx="0.0005425509013609"
        ixy="1.6462822586351E-36"
        ixz="-3.47849161919726E-20"
        iyy="0.0005425509013609"
        iyz="1.56187225364287E-22"
        izz="1.66721257729828E-05" />
    </inertial>

    <visual>
      <origin
        xyz="0 0 0"
        rpy="0 0 0" />
      <geometry>
      <mesh filename="package://autonomous_robot_description/meshes/front_hinge.stl" />
      </geometry>
      <material
        name="">
        <color
          rgba="0.792156862745098 0.819607843137255 0.933333333333333 1" />
      </material>
    </visual>

    <collision>
      <origin
        xyz="0 0 0"
        rpy="0 0 0" />
      <geometry>
      <mesh filename="package://autonomous_robot_description/meshes/front_hinge.stl" />

      </geometry>
    </collision>
  </link>

  <joint
    name="front_hinge_joint"
    type="revolute">
    <origin
      xyz="0.48615 3E-05 -0.249"
      rpy="0 0 0" />
    <parent
      link="base_link" />
    <child
      link="front_hinge" />
    <axis
      xyz="0 0 -1" />
    <limit
      lower="0"
      upper="0"
      effort="10"
      velocity="10" />
    <dynamics
      friction="0.1" />
  </joint>

  <link
    name="front_wheel_link">
    <inertial>
      <origin
        xyz="-0.00525364785120086 -1.55099892684973E-05 0.0174290152973623"
        rpy="0 0 0" />
      <mass
        value="0.352967556141925" />
      <inertia
        ixx="0.00073004158852838"
        ixy="9.61802000401493E-08"
        ixz="0.000121568718275352"
        iyy="0.00101429227078045"
        iyz="1.87365885942766E-07"
        izz="0.000367004018839029" />
    </inertial>

    <visual>
      <origin
        xyz="0 0 0"
        rpy="0 0 0" />
      <geometry>
          <mesh filename="package://autonomous_robot_description/meshes/front_wheel_link.stl" />
      </geometry>
      <material
        name="">
        <color
          rgba="0.792156862745098 0.819607843137255 0.933333333333333 1" />
      </material>
    </visual>
    
    <collision>
      <origin
        xyz="0 0 0"
        rpy="0 0 0" />
      <geometry>
         <mesh filename="package://autonomous_robot_description/meshes/front_wheel_link.stl" />
      </geometry>
    </collision>

  </link>

  <joint
    name="front_wheel_joint"
    type="fixed">
    <origin
      xyz="0.026678 0 -0.101"
      rpy="0 0 0" />
    <parent
      link="front_hinge" />
    <child
      link="front_wheel_link" />
    <axis
      xyz="0 0 0" />
  </joint>

  <link
    name="left_wheel_link">
    <inertial>
      <origin
        xyz="-1.90751666109268E-05 -0.0583143245180203 2.8460548917586E-09"
        rpy="0 0 0" />
      <mass
        value="3.02704875281272" />
      <inertia
        ixx="0.020879182250798"
        ixy="-2.82489897551829E-06"
        ixz="6.07375197746533E-09"
        iyy="0.0331000539100534"
        iyz="-1.0325721327057E-10"
        izz="0.0208828083641725" />
    </inertial>

    <visual>
      <origin
        xyz="0 0 0"
        rpy="0 0 0" />
      <geometry>
      <mesh filename="package://autonomous_robot_description/meshes/left_wheel_link.stl" />

      </geometry>
      <material
        name="">
        <color
          rgba="0.752941176470588 0.752941176470588 0.752941176470588 1" />
      </material>
    </visual>
    
    <collision>
      <origin
        xyz="0 0 0"
        rpy="0 0 0" />
      <geometry>
          <mesh filename="package://autonomous_robot_description/meshes/left_wheel_link.stl" />
      </geometry>
    </collision>
  </link>

  <joint
    name="left_wheel_joint"
    type="continuous">
    <origin
      xyz="0.0064024 0.29733 -0.22493"
      rpy="0 0 0" />
    <parent
      link="base_link" />
    <child
      link="left_wheel_link" />
    <axis
      xyz="0 1 0" />
    <limit
      effort="100"
      velocity="100" />
    <dynamics
      friction="0.1" />
  </joint>

  <link
    name="rear_hinge">
    <inertial>
      <origin
        xyz="-1.92235116713846E-13 -1.06920028386526E-12 0.104803731952705"
        rpy="0 0 0" />
      <mass
        value="0.146953839835609" />
      <inertia
        ixx="0.000542550901360898"
        ixy="5.70186614177259E-34"
        ixz="-1.85421954433821E-18"
        iyy="0.000542550901360898"
        iyz="2.51645457634199E-21"
        izz="1.66721257729828E-05" />
    </inertial>
    <visual>
      <origin
        xyz="0 0 0"
        rpy="0 0 0" />
      <geometry>
          <mesh filename="package://autonomous_robot_description/meshes/rear_hinge.stl" />
      </geometry>
      <material
        name="">
        <color
          rgba="0.792156862745098 0.819607843137255 0.933333333333333 1" />
      </material>
    </visual>
    <collision>
      <origin
        xyz="0 0 0"
        rpy="0 0 0" />
      <geometry>
          <mesh filename="package://autonomous_robot_description/meshes/rear_hinge.stl" />
      </geometry>
    </collision>
  </link>

  <joint
    name="rear_hinge_joint"
    type="revolute">
    <origin
      xyz="-0.47385 3E-05 -0.249"
      rpy="0 0 0" />
    <parent
      link="base_link" />
    <child
      link="rear_hinge" />
    <axis
      xyz="0 0 -1" />
    <limit
      lower="0"
      upper="0"
      effort="10"
      velocity="10" />
    <dynamics
      friction="0.1" />
  </joint>

  <link
    name="rear_wheel_link">
    <inertial>
      <origin
        xyz="-0.00525364785138838 -1.55099903700051E-05 0.0174290152973615"
        rpy="0 0 0" />
      <mass
        value="0.352967556141925" />
      <inertia
        ixx="0.000730041588528382"
        ixy="9.61802000397574E-08"
        ixz="0.000121568718275352"
        iyy="0.00101429227078046"
        iyz="1.87365885942579E-07"
        izz="0.00036700401883903" />
    </inertial>

    <visual>
      <origin
        xyz="0 0 0"
        rpy="0 0 0" />
      <geometry>
        <mesh filename="package://autonomous_robot_description/meshes/rear_wheel_link.stl" />
      </geometry>
      <material
        name="">
        <color
          rgba="0.792156862745098 0.819607843137255 0.933333333333333 1" />
      </material>
    </visual>

    <collision>
      <origin
        xyz="0 0 0"
        rpy="0 0 0" />
      <geometry>
         <mesh filename="package://autonomous_robot_description/meshes/rear_wheel_link.stl" />
      </geometry>
    </collision>
  </link>

  <joint
    name="rear_wheel_joint"
    type="fixed">
    <origin
      xyz="0.026678 0 -0.101"
      rpy="0 0 0" />
    <parent
      link="rear_hinge" />
    <child
      link="rear_wheel_link" />
    <axis
      xyz="0 0 0" />
  </joint>

  <link
    name="right_wheel_link">
    <inertial>
      <origin
        xyz="-1.90759469208546E-05 0.0582856760499313 2.84605594647047E-09"
        rpy="0 0 0" />
      <mass
        value="3.02704880758978" />
      <inertia
        ixx="0.0208791824415697"
        ixy="-2.82482025914986E-06"
        ixz="6.07375181847265E-09"
        iyy="0.0331000541778796"
        iyz="-1.03257351645427E-10"
        izz="0.0208828085549403" />
    </inertial>

    <visual>
      <origin
        xyz="0 0 0"
        rpy="0 0 0" />
      <geometry>
          <mesh filename="package://autonomous_robot_description/meshes/right_wheel_link.stl" />
      </geometry>
      <material
        name="">
        <color
          rgba="0.752941176470588 0.752941176470588 0.752941176470588 1" />
      </material>
    </visual>

    <collision>
      <origin
        xyz="0 0 0"
        rpy="0 0 0" />
      <geometry>
          <mesh filename="package://autonomous_robot_description/meshes/right_wheel_link.stl" />
      </geometry>
    </collision>
  </link>

  <joint
    name="right_wheel_joint"
    type="continuous">
    <origin
      xyz="0.0064024 -0.29727 -0.22493"
      rpy="0 0 0" />
    <parent
      link="base_link" />
    <child
      link="right_wheel_link" />
    <axis
      xyz="0 1 0" />
    <limit
      effort="100"
      velocity="100" />
    <dynamics
      friction="0.1" />
  </joint>

  <link
    name="camera_link">
    <inertial>
      <origin
        xyz="-0.00197487895030868 0.000642205545098973 -0.011631218801564"
        rpy="0 0 0" />
      <mass
        value="0.165291294407499" />
      <inertia
        ixx="0.000122677784636091"
        ixy="1.66379193010169E-06"
        ixz="-1.44487316744383E-06"
        iyy="7.25411975192449E-05"
        iyz="1.1220571332297E-06"
        izz="0.000106349287979594" />
    </inertial>
    <visual>
      <origin
        xyz="0 0 0"
        rpy="0 0 0" />
      <geometry>
          <mesh filename="package://autonomous_robot_description/meshes/camera_link.stl" />
      </geometry>
      <material
        name="">
        <color
          rgba="1 1 1 1" />
      </material>
    </visual>
    <collision>
      <origin
        xyz="0 0 0"
        rpy="0 0 0" />
      <geometry>
        <mesh filename="package://autonomous_robot_description/meshes/camera_link.stl" />
      </geometry>
    </collision>
  </link>

  <joint
    name="base_camera_joint"
    type="fixed">
    <origin
      xyz="0.23677 3.0058E-05 0.03967"
      rpy="0 0 0" />
    <parent
      link="base_link" />
    <child
      link="camera_link" />
    <axis
      xyz="0 0 0" />
  </joint>



  <link
    name="lidar_link">
    <inertial>
      <origin
        xyz="-3.17066240373975E-06 0.000590605162272828 -0.00345445998991967"
        rpy="0 0 0" />
      <mass
        value="0.627783620462149" />
      <inertia
        ixx="0.00073292617814455"
        ixy="-1.35890547511391E-09"
        ixz="-6.4072150674834E-08"
        iyy="0.000714794924662058"
        iyz="1.41933297263802E-05"
        izz="0.000851160993650038" />
    </inertial>
    <visual>
      <origin
        xyz="0 0 0"
        rpy="0 0 0" />
      <geometry>
          <mesh filename="package://autonomous_robot_description/meshes/lidar_link.stl" />
      </geometry>
      <material
        name="">
        <color
          rgba="0.00784313725490196 0.23921568627451 0.823529411764706 1" />
      </material>
    </visual>
    <collision>
      <origin
        xyz="0 0 0"
        rpy="0 0 0" />
      <geometry>
          <mesh filename="package://autonomous_robot_description/meshes/lidar_link.stl" />
      </geometry>
    </collision>
  </link>

  <joint
    name="base_lidar_joint"
    type="fixed">
    <origin
      xyz="0.0011524 3E-05 0.1424"
      rpy="0 0 -1.5708" />
    <parent
      link="base_link" />
    <child
      link="lidar_link" />
    <axis
      xyz="0 0 0" />
  </joint>
</robot>